Time slot   0
ld_routine
	Loaded a process at input/proc/p0s, PID: 1 PRIO: 130
	CPU 3: Dispatched process  1
Time slot   1
Time slot   2
Page table dump from addr 0 to 18446744073709551615
Page 0 -> PTE Value: 80000000
Page 1 -> PTE Value: 80000001
	Loaded a process at input/proc/m0s, PID: 2 PRIO: 120
	CPU 3: Put process  1 to run queue
	CPU 3: Dispatched process  2
Page table dump from addr 0 to 18446744073709551615
Page 0 -> PTE Value: 80000002
Page 1 -> PTE Value: 80000003
	CPU 1: Dispatched process  1
Time slot   3
Page table dump from addr 0 to 18446744073709551615
Page 0 -> PTE Value: 80000002
Page 1 -> PTE Value: 80000003
Page 2 -> PTE Value: 80000004
Page 3 -> PTE Value: 80000005
Page table dump from addr 0 to 18446744073709551615
Page 0 -> PTE Value: 80000002
Page 1 -> PTE Value: 80000003
Page 2 -> PTE Value: 80000004
Page 3 -> PTE Value: 80000005
Page 4 -> PTE Value: 80000006
libfree:205
Page table dump from addr 0 to 18446744073709551615
Page 0 -> PTE Value: 80000002
Page 1 -> PTE Value: 80000003
Page 2 -> PTE Value: 80000004
Page 3 -> PTE Value: 80000005
Page 4 -> PTE Value: 80000006
Time slot   4
	Loaded a process at input/proc/s1, PID: 3 PRIO: 0
	CPU 3: Put process  2 to run queue
	CPU 3: Dispatched process  3
	CPU 1: Put process  1 to run queue
	CPU 1: Dispatched process  2
Time slot   5
	CPU 0: Dispatched process  1
Page table dump from addr 0 to 18446744073709551615
Page 0 -> PTE Value: 80000007
Page table dump from addr 0 to 18446744073709551615
Page 0 -> PTE Value: 80000007
Time slot   6
Page table dump from addr 0 to 18446744073709551615
Page 0 -> PTE Value: 80000007
	Loaded a process at input/proc/p1s, PID: 4 PRIO: 15
	CPU 3: Put process  3 to run queue
	CPU 3: Dispatched process  3
	CPU 1: Put process  2 to run queue
	CPU 1: Dispatched process  4
Time slot   7
	CPU 0: Put process  1 to run queue
	CPU 0: Dispatched process  2
	CPU 2: Dispatched process  1
libread:365
Page table dump from addr 0 to 18446744073709551615
Time slot   8
	Loaded a process at input/proc/s3, PID: 5 PRIO: 39
	CPU 3: Put process  3 to run queue
	CPU 3: Dispatched process  3
	CPU 2: Put process  1 to run queue
	CPU 2: Dispatched process  5
	CPU 1: Put process  4 to run queue
	CPU 1: Dispatched process  1
libread:365
Page table dump from addr 0 to 18446744073709551615
Time slot   9
	CPU 0: Processed  2 has finished
	CPU 0: Dispatched process  4
Time slot  10
	Loaded a process at input/proc/s2, PID: 6 PRIO: 120
	CPU 3: Put process  3 to run queue
	CPU 3: Dispatched process  6
	CPU 2: Put process  5 to run queue
	CPU 2: Dispatched process  3
	CPU 1: Put process  1 to run queue
	CPU 1: Dispatched process  5
Time slot  11
	CPU 0: Put process  4 to run queue
	CPU 0: Dispatched process  1
libread:365
Page table dump from addr 0 to 18446744073709551615
	Loaded a process at input/proc/m1s, PID: 7 PRIO: 15
	CPU 2: Processed  3 has finished
	CPU 2: Dispatched process  4
Time slot  12
	Loaded a process at input/proc/s0, PID: 8 PRIO: 38
	CPU 3: Put process  6 to run queue
	CPU 3: Dispatched process  7
Page table dump from addr 0 to 18446744073709551615
	CPU 1: Put process  5 to run queue
	CPU 1: Dispatched process  8
Time slot  13
	CPU 0: Put process  1 to run queue
	CPU 0: Dispatched process  5
Page table dump from addr 0 to 18446744073709551615
	CPU 2: Put process  4 to run queue
	CPU 2: Dispatched process  6
Time slot  14
	CPU 3: Put process  7 to run queue
	CPU 3: Dispatched process  1
	CPU 1: Put process  8 to run queue
	CPU 1: Dispatched process  4
Time slot  15
	CPU 0: Put process  5 to run queue
	CPU 0: Dispatched process  7
libfree:205
Page table dump from addr 0 to 18446744073709551615
	CPU 2: Put process  6 to run queue
	CPU 2: Dispatched process  8
Time slot  16
Page table dump from addr 0 to 18446744073709551615
	CPU 3: Processed  1 has finished
	CPU 3: Dispatched process  5
	CPU 1: Put process  4 to run queue
	CPU 1: Dispatched process  6
Time slot  17
	CPU 0: Put process  7 to run queue
	CPU 0: Dispatched process  4
	CPU 2: Put process  8 to run queue
	CPU 2: Dispatched process  7
libfree:205
Page table dump from addr 0 to 18446744073709551615
Time slot  18
	CPU 3: Put process  5 to run queue
	CPU 3: Dispatched process  8
libfree:205
Page table dump from addr 0 to 18446744073709551615
	CPU 1: Put process  6 to run queue
	CPU 1: Dispatched process  5
Time slot  19
	CPU 0: Processed  4 has finished
	CPU 0: Dispatched process  6
	CPU 2: Processed  7 has finished
	CPU 2 stopped
Time slot  20
	CPU 3: Put process  8 to run queue
	CPU 3: Dispatched process  8
	CPU 1: Put process  5 to run queue
	CPU 1: Dispatched process  5
Time slot  21
	CPU 0: Put process  6 to run queue
	CPU 0: Dispatched process  6
	CPU 1: Processed  5 has finished
	CPU 1 stopped
Time slot  22
	CPU 3: Put process  8 to run queue
	CPU 3: Dispatched process  8
Time slot  23
	CPU 0: Put process  6 to run queue
	CPU 0: Dispatched process  6
Time slot  24
	CPU 3: Put process  8 to run queue
	CPU 3: Dispatched process  8
Time slot  25
	CPU 0: Processed  6 has finished
	CPU 0 stopped
Time slot  26
Time slot  27
	CPU 3: Put process  8 to run queue
	CPU 3: Dispatched process  8
Time slot  28
Time slot  29
	CPU 3: Put process  8 to run queue
	CPU 3: Dispatched process  8
Time slot  30
	CPU 3: Processed  8 has finished
	CPU 3 stopped
