Time slot   0
ld_routine
	Loaded a process at input/proc/p1s, PID: 1 PRIO: 15
	CPU 3: Dispatched process  1
Time slot   1
Time slot   2
	CPU 3: Put process  1 to run queue
	CPU 3: Dispatched process  1
Time slot   3
Time slot   4
	Loaded a process at input/proc/m0s, PID: 2 PRIO: 120
	CPU 3: Put process  1 to run queue
	CPU 3: Dispatched process  2
	CPU 2: Dispatched process  1
Time slot   5
Page table dump from addr 0 to 18446744073709551615
Page 0 -> PTE Value: 80000000
Page 1 -> PTE Value: 80000001
Page table dump from addr 0 to 18446744073709551615
Page 0 -> PTE Value: 80000000
Page 1 -> PTE Value: 80000001
Page 2 -> PTE Value: 80000002
Time slot   6
	Loaded a process at input/proc/p0s, PID: 3 PRIO: 130
	CPU 3: Put process  2 to run queue
	CPU 3: Dispatched process  2
	CPU 2: Put process  1 to run queue
	CPU 2: Dispatched process  3
Time slot   7
	CPU 0: Dispatched process  1
Page table dump from addr 0 to 18446744073709551615
Page 0 -> PTE Value: 80000003
Time slot   8
Page table dump from addr 0 to 18446744073709551615
Page 0 -> PTE Value: 80000003
Page 1 -> PTE Value: 80000004
Page 2 -> PTE Value: 80000005
	Loaded a process at input/proc/s0, PID: 4 PRIO: 38
	CPU 3: Put process  2 to run queue
	CPU 3: Dispatched process  4
	CPU 2: Put process  3 to run queue
	CPU 2: Dispatched process  2
Time slot   9
	CPU 0: Put process  1 to run queue
	CPU 0: Dispatched process  3
Page table dump from addr 0 to 18446744073709551615
Page 0 -> PTE Value: 80000006
Page 1 -> PTE Value: 80000007
	CPU 1: Dispatched process  1
Time slot  10
	Loaded a process at input/proc/s3, PID: 5 PRIO: 39
	CPU 3: Put process  4 to run queue
	CPU 3: Dispatched process  4
	CPU 2: Processed  2 has finished
	CPU 2: Dispatched process  5
Time slot  11
	CPU 0: Put process  3 to run queue
	CPU 0: Dispatched process  3
Page table dump from addr 0 to 18446744073709551615
Page 0 -> PTE Value: 80000008
	CPU 1: Processed  1 has finished
Time slot  12
Page table dump from addr 0 to 18446744073709551615
Page 0 -> PTE Value: 80000008
	CPU 3: Put process  4 to run queue
	CPU 3: Dispatched process  4
Time slot  13
	CPU 0: Put process  3 to run queue
	CPU 0: Dispatched process  3
libread:365
Page table dump from addr 0 to 18446744073709551615
Page 0 -> PTE Value: 80000008
	CPU 2: Put process  5 to run queue
	CPU 2: Dispatched process  5
	Loaded a process at input/proc/m1s, PID: 6 PRIO: 15
	CPU 1: Dispatched process  6
Time slot  14
Page table dump from addr 0 to 18446744073709551615
Page 0 -> PTE Value: 80000009
Page 1 -> PTE Value: 8000000a
	CPU 2: Put process  5 to run queue
	CPU 2: Dispatched process  5
	CPU 3: Put process  4 to run queue
	CPU 3: Dispatched process  4
Time slot  15
	CPU 0: Put process  3 to run queue
	CPU 0: Dispatched process  3
libread:365
Page table dump from addr 0 to 18446744073709551615
Page 0 -> PTE Value: 80000009
Page 1 -> PTE Value: 8000000a
Page table dump from addr 0 to 18446744073709551615
Page 0 -> PTE Value: 80000009
Page 1 -> PTE Value: 8000000a
Page 2 -> PTE Value: 8000000b
	Loaded a process at input/proc/s2, PID: 7 PRIO: 120
	CPU 1: Put process  6 to run queue
	CPU 1: Dispatched process  6
Time slot  16
	CPU 3: Put process  4 to run queue
	CPU 3: Dispatched process  4
	CPU 2: Put process  5 to run queue
	CPU 2: Dispatched process  5
Page table dump from addr 0 to 18446744073709551615
Page 0 -> PTE Value: 8000000c
Time slot  17
	CPU 0: Put process  3 to run queue
	CPU 0: Dispatched process  7
	Loaded a process at input/proc/s1, PID: 8 PRIO: 0
Time slot  18
	CPU 1: Put process  6 to run queue
	CPU 1: Dispatched process  3
libread:365
Page table dump from addr 0 to 18446744073709551615
	CPU 3: Put process  4 to run queue
	CPU 3: Dispatched process  8
	CPU 2: Put process  5 to run queue
	CPU 2: Dispatched process  6
Time slot  19
	CPU 0: Put process  7 to run queue
	CPU 0: Dispatched process  4
	CPU 1: Put process  3 to run queue
	CPU 1: Dispatched process  5
Time slot  20
	CPU 3: Put process  8 to run queue
	CPU 3: Dispatched process  7
	CPU 2: Processed  6 has finished
	CPU 2: Dispatched process  3
Time slot  21
	CPU 0: Put process  4 to run queue
	CPU 0: Dispatched process  8
	CPU 1: Put process  5 to run queue
	CPU 1: Dispatched process  4
Time slot  22
	CPU 3: Put process  7 to run queue
	CPU 3: Dispatched process  5
	CPU 2: Processed  3 has finished
	CPU 2: Dispatched process  7
Time slot  23
	CPU 0: Put process  8 to run queue
	CPU 0: Dispatched process  8
	CPU 3: Processed  5 has finished
	CPU 3 stopped
	CPU 1: Put process  4 to run queue
	CPU 1: Dispatched process  4
Time slot  24
	CPU 2: Put process  7 to run queue
	CPU 2: Dispatched process  7
	CPU 1: Processed  4 has finished
	CPU 1 stopped
Time slot  25
	CPU 0: Put process  8 to run queue
	CPU 0: Dispatched process  8
Time slot  26
	CPU 0: Processed  8 has finished
	CPU 0 stopped
Time slot  27
	CPU 2: Put process  7 to run queue
	CPU 2: Dispatched process  7
Time slot  28
Time slot  29
	CPU 2: Put process  7 to run queue
	CPU 2: Dispatched process  7
Time slot  30
Time slot  31
	CPU 2: Processed  7 has finished
	CPU 2 stopped
