Time slot   0
ld_routine
Time slot   1
	Loaded a process at input/proc/p1s, PID: 1 PRIO: 15
Time slot   2
	CPU 3: Dispatched process  1
Time slot   3
Time slot   4
	CPU 3: Put process  1 to run queue
	CPU 3: Dispatched process  1
Time slot   5
	Loaded a process at input/proc/m0s, PID: 2 PRIO: 120
Time slot   6
	CPU 3: Put process  1 to run queue
	CPU 3: Dispatched process  1
	CPU 2: Dispatched process  2
liballoc:178
print_pgtbl:
 PDG=b4afc220b3908710 P4g=b4afc220b3909720 PUD=b4afc220b390a730 PMD=b4afc220b390b740
Time slot   7
	Loaded a process at input/proc/p0s, PID: 3 PRIO: 130
liballoc:178
print_pgtbl:
 PDG=b4afc220b390f040 P4g=b4afc220b3910050 PUD=b4afc220b3911060 PMD=b4afc220b3912070
Time slot   8
	CPU 3: Put process  1 to run queue
	CPU 3: Dispatched process  1
	CPU 1: Dispatched process  3
	CPU 2: Put process  2 to run queue
	CPU 2: Dispatched process  2
libfree:218
print_pgtbl:
 PDG=b4afc230b390f040 P4g=b4afc230b3910050 PUD=b4afc230b3911060 PMD=b4afc230b3912070
Time slot   9
	Loaded a process at input/proc/s0, PID: 4 PRIO: 38
liballoc:178
print_pgtbl:
 PDG=b52fd220b3915970 P4g=b52fd220b3916980 PUD=b52fd220b3917990 PMD=b52fd220b39189a0
liballoc:178
print_pgtbl:
 PDG=b4afc220b3915970 P4g=b4afc220b3916980 PUD=b4afc220b3917990 PMD=b4afc220b39189a0
Time slot  10
	CPU 3: Put process  1 to run queue
	CPU 3: Dispatched process  1
	CPU 1: Put process  3 to run queue
	CPU 1: Dispatched process  4
	CPU 2: Put process  2 to run queue
	CPU 2: Dispatched process  2
libwrite:502
print_pgtbl:
 PDG=b4afc210b3915970 P4g=b4afc210b3916980 PUD=b4afc210b3917990 PMD=b4afc210b39189a0
	CPU 0: Dispatched process  3
liballoc:178
print_pgtbl:
 PDG=b5afe220b3915970 P4g=b5afe220b3916980 PUD=b5afe220b3917990 PMD=b5afe220b39189a0
Time slot  11
libwrite:502
print_pgtbl:
 PDG=b4afc210b3915970 P4g=b4afc210b3916980 PUD=b4afc210b3917990 PMD=b4afc210b39189a0
libfree:218
print_pgtbl:
 PDG=b5afe230b3915970 P4g=b5afe230b3916980 PUD=b5afe230b3917990 PMD=b5afe230b39189a0
	Loaded a process at input/proc/s3, PID: 5 PRIO: 39
Time slot  12
	CPU 3: Put process  1 to run queue
	CPU 3: Dispatched process  1
	CPU 1: Put process  4 to run queue
	CPU 1: Dispatched process  4
	CPU 2: Processed  2 has finished
	CPU 2: Dispatched process  5
	CPU 0: Put process  3 to run queue
	CPU 0: Dispatched process  3
liballoc:178
print_pgtbl:
 PDG=b5afe220b391c480 P4g=b5afe220b391d490 PUD=b5afe220b391e4a0 PMD=b5afe220b391f4b0
Time slot  13
libwrite:502
print_pgtbl:
 PDG=b5afe210b391c480 P4g=b5afe210b391d490 PUD=b5afe210b391e4a0 PMD=b5afe210b391f4b0
Time slot  14
	CPU 3: Put process  1 to run queue
	CPU 3: Dispatched process  1
	CPU 1: Put process  4 to run queue
	CPU 1: Dispatched process  4
	CPU 2: Put process  5 to run queue
	CPU 2: Dispatched process  5
	CPU 0: Put process  3 to run queue
	CPU 0: Dispatched process  3
	Loaded a process at input/proc/m1s, PID: 6 PRIO: 15
Time slot  15
libread:426
Time slot  16
	CPU 3: Put process  1 to run queue
	CPU 3: Dispatched process  6
	CPU 2: Put process  5 to run queue
	CPU 2: Dispatched process  1
	CPU 1: Put process  4 to run queue
	CPU 1: Dispatched process  4
	CPU 0: Put process  3 to run queue
	CPU 0: Dispatched process  5
	Loaded a process at input/proc/s2, PID: 7 PRIO: 120
liballoc:178
print_pgtbl:
 PDG=b42fb220b3929580 P4g=b42fb220b392a590 PUD=b42fb220b392b5a0 PMD=b42fb220b392c5b0
Time slot  17
	Loaded a process at input/proc/s1, PID: 8 PRIO: 0
liballoc:178
print_pgtbl:
 PDG=b42fb220b392fde0 P4g=b42fb220b3930df0 PUD=b42fb220b3931e00 PMD=b42fb220b3932e10
Time slot  18
	CPU 3: Put process  6 to run queue
	CPU 3: Dispatched process  8
	CPU 2: Put process  1 to run queue
	CPU 2: Dispatched process  6
libfree:218
print_pgtbl:
 PDG=b4afc230b392fde0 P4g=b4afc230b3930df0 PUD=b4afc230b3931e00 PMD=b4afc230b3932e10
	CPU 1: Put process  4 to run queue
	CPU 1: Dispatched process  1
	CPU 0: Put process  5 to run queue
	CPU 0: Dispatched process  4
Time slot  19
liballoc:178
print_pgtbl:
 PDG=b4afc220b392fde0 P4g=b4afc220b3930df0 PUD=b4afc220b3931e00 PMD=b4afc220b3932e10
Time slot  20
	CPU 3: Put process  8 to run queue
	CPU 3: Dispatched process  8
	CPU 1: Put process  1 to run queue
	CPU 1: Dispatched process  1
	CPU 2: Put process  6 to run queue
	CPU 2: Dispatched process  6
libfree:218
print_pgtbl:
 PDG=b4afc230b392fde0 P4g=b4afc230b3930df0 PUD=b4afc230b3931e00 PMD=b4afc230b3932e10
	CPU 0: Put process  4 to run queue
	CPU 0: Dispatched process  4
Time slot  21
	CPU 1: Processed  1 has finished
	CPU 1: Dispatched process  5
libfree:218
print_pgtbl:
 PDG=b4afc230b392fde0 P4g=b4afc230b3930df0 PUD=b4afc230b3931e00 PMD=b4afc230b3932e10
Time slot  22
	CPU 3: Put process  8 to run queue
	CPU 3: Dispatched process  8
	CPU 2: Processed  6 has finished
	CPU 2: Dispatched process  7
	CPU 0: Put process  4 to run queue
	CPU 0: Dispatched process  4
Time slot  23
	CPU 1: Put process  5 to run queue
	CPU 1: Dispatched process  5
Time slot  24
	CPU 3: Put process  8 to run queue
	CPU 3: Dispatched process  8
	CPU 2: Put process  7 to run queue
	CPU 2: Dispatched process  7
	CPU 0: Put process  4 to run queue
	CPU 0: Dispatched process  4
Time slot  25
	CPU 1: Put process  5 to run queue
	CPU 1: Dispatched process  5
	CPU 0: Processed  4 has finished
	CPU 0: Dispatched process  3
Time slot  26
	CPU 3: Put process  8 to run queue
	CPU 3: Dispatched process  8
	CPU 2: Put process  7 to run queue
	CPU 2: Dispatched process  7
libfree:218
print_pgtbl:
 PDG=b5afe230b392fde0 P4g=b5afe230b3930df0 PUD=b5afe230b3931e00 PMD=b5afe230b3932e10
Time slot  27
	CPU 3: Processed  8 has finished
	CPU 3 stopped
	CPU 1: Put process  5 to run queue
	CPU 1: Dispatched process  5
	CPU 0: Put process  3 to run queue
	CPU 0: Dispatched process  3
libwrite:502
print_pgtbl:
 PDG=b5afe210b392fde0 P4g=b5afe210b3930df0 PUD=b5afe210b3931e00 PMD=b5afe210b3932e10
Time slot  28
	CPU 2: Put process  7 to run queue
	CPU 2: Dispatched process  7
Time slot  29
	CPU 1: Put process  5 to run queue
	CPU 1: Dispatched process  5
	CPU 0: Put process  3 to run queue
	CPU 0: Dispatched process  3
libread:426
Time slot  30
	CPU 2: Put process  7 to run queue
	CPU 2: Dispatched process  7
libwrite:502
print_pgtbl:
 PDG=b5afe210b392fde0 P4g=b5afe210b3930df0 PUD=b5afe210b3931e00 PMD=b5afe210b3932e10
Time slot  31
	CPU 1: Processed  5 has finished
	CPU 1 stopped
	CPU 0: Put process  3 to run queue
	CPU 0: Dispatched process  3
libread:426
Time slot  32
	CPU 2: Put process  7 to run queue
	CPU 2: Dispatched process  7
	CPU 0: Processed  3 has finished
	CPU 0 stopped
Time slot  33
Time slot  34
	CPU 2: Processed  7 has finished
	CPU 2 stopped
