Time slot   0
ld_routine
Time slot   1
	Loaded a process at input/proc/s3, PID: 1 PRIO: 3
	CPU 0: Dispatched process  1
Time slot   2
Time slot   3
	Loaded a process at input/proc/m2s, PID: 2 PRIO: 3
	CPU 0: Put process  1 to run queue
	CPU 0: Dispatched process  2
print_pgtbl:
 PDG=  0x7f468400e380 PDG=  0x7f468400e380 P4g=  0x7f468400f390 PUD=  0x7f46840103a0 PMD=  0x7f46840113b0
Time slot   4
print_pgtbl:
 PDG=  0x7f468400e380 PDG=  0x7f468400e380 P4g=  0x7f468400f390 PUD=  0x7f46840103a0 PMD=  0x7f46840113b0
Time slot   5
	Loaded a process at input/proc/s2, PID: 3 PRIO: 3
	CPU 0: Put process  2 to run queue
	CPU 0: Dispatched process  1
Time slot   6
Time slot   7
	CPU 0: Put process  1 to run queue
	CPU 0: Dispatched process  3
Time slot   8
Time slot   9
	CPU 0: Put process  3 to run queue
	CPU 0: Dispatched process  2
print_pgtbl:
 PDG=  0x7f4684014f50 PDG=  0x7f4684014f50 P4g=  0x7f4684015f60 PUD=  0x7f4684016f70 PMD=  0x7f4684017f80
Time slot  10
Time slot  11
	Loaded a process at input/proc/m2s, PID: 4 PRIO: 2
	CPU 0: Put process  2 to run queue
	CPU 0: Dispatched process  4
print_pgtbl:
 PDG=  0x7f468401bb20 PDG=  0x7f468401bb20 P4g=  0x7f468401cb30 PUD=  0x7f468401db40 PMD=  0x7f468401eb50
Time slot  12
print_pgtbl:
 PDG=  0x7f468401bb20 PDG=  0x7f468401bb20 P4g=  0x7f468401cb30 PUD=  0x7f468401db40 PMD=  0x7f468401eb50
	CPU 0: Put process  4 to run queue
	CPU 0: Dispatched process  4
print_pgtbl:
 PDG=  0x7f468401bb20 PDG=  0x7f468401bb20 P4g=  0x7f468401cb30 PUD=  0x7f468401db40 PMD=  0x7f468401eb50
Time slot  13
Time slot  14
Time slot  15
	CPU 0: Put process  4 to run queue
	CPU 0: Dispatched process  4
Time slot  16
	Loaded a process at input/proc/s1, PID: 5 PRIO: 0
	CPU 0: Put process  4 to run queue
	CPU 0: Dispatched process  5
Time slot  17
Time slot  18
	CPU 0: Put process  5 to run queue
	CPU 0: Dispatched process  5
Time slot  19
Time slot  20
	CPU 0: Put process  5 to run queue
	CPU 0: Dispatched process  5
Time slot  21
Time slot  22
Time slot  23
	CPU 0: Put process  5 to run queue
	CPU 0: Dispatched process  5
Time slot  24
	CPU 0: Put process  5 to run queue
	CPU 0: Dispatched process  5
Time slot  25
Time slot  26
	CPU 0: Processed  5 has finished
	CPU 0: Dispatched process  4
Time slot  27
Time slot  28
	CPU 0: Put process  4 to run queue
	CPU 0: Dispatched process  4
print_pgtbl:
 PDG=  0x7f4684022670 PDG=  0x7f4684022670 P4g=  0x7f4684023680 PUD=  0x7f4684024690 PMD=  0x7f46840256a0
Time slot  29
Time slot  30
	CPU 0: Put process  4 to run queue
	CPU 0: Dispatched process  4
print_pgtbl:
 PDG=  0x7f4684022670 PDG=  0x7f4684022670 P4g=  0x7f4684023680 PUD=  0x7f4684024690 PMD=  0x7f46840256a0
Time slot  31
print_pgtbl:
 PDG=  0x7f4684022670 PDG=  0x7f4684022670 P4g=  0x7f4684023680 PUD=  0x7f4684024690 PMD=  0x7f46840256a0
Time slot  32
	CPU 0: Processed  4 has finished
	CPU 0: Dispatched process  1
Time slot  33
	CPU 0: Put process  1 to run queue
	CPU 0: Dispatched process  3
Time slot  34
Time slot  35
Time slot  36
	CPU 0: Put process  3 to run queue
	CPU 0: Dispatched process  2
Time slot  37
Time slot  38
	CPU 0: Put process  2 to run queue
	CPU 0: Dispatched process  1
Time slot  39
Time slot  40
	CPU 0: Put process  1 to run queue
	CPU 0: Dispatched process  3
Time slot  41
Time slot  42
	CPU 0: Put process  3 to run queue
	CPU 0: Dispatched process  2
Time slot  43
Time slot  44
	CPU 0: Put process  2 to run queue
	CPU 0: Dispatched process  1
Time slot  45
Time slot  46
	CPU 0: Put process  1 to run queue
	CPU 0: Dispatched process  3
Time slot  47
Time slot  48
	CPU 0: Put process  3 to run queue
	CPU 0: Dispatched process  2
Time slot  49
Time slot  50
	CPU 0: Put process  2 to run queue
	CPU 0: Dispatched process  1
Time slot  51
Time slot  52
	CPU 0: Put process  1 to run queue
	CPU 0: Dispatched process  3
Time slot  53
	CPU 0: Put process  3 to run queue
	CPU 0: Dispatched process  2
Time slot  54
Time slot  55
Time slot  56
	CPU 0: Processed  2 has finished
	CPU 0: Dispatched process  1
Time slot  57
	CPU 0: Put process  1 to run queue
	CPU 0: Dispatched process  3
Time slot  58
Time slot  59
Time slot  60
	CPU 0: Processed  3 has finished
	CPU 0: Dispatched process  1
Time slot  61
Time slot  62
	CPU 0: Processed  1 has finished
	CPU 0 stopped
