Time slot   0
ld_routine
Time slot   1
Time slot   2
Time slot   3
Time slot   4
Time slot   5
	Loaded a process at input/proc/m2s, PID: 1 PRIO: 120
Time slot   6
	CPU 2: Dispatched process  1
print_pgtbl:
 PDG=  0x7f971c007710 PDG=  0x7f971c007710 P4g=  0x7f971c008720 PUD=  0x7f971c009730 PMD=  0x7f971c00a740
Time slot   7
print_pgtbl:
 PDG=  0x7f971c007710 PDG=  0x7f971c007710 P4g=  0x7f971c008720 PUD=  0x7f971c009730 PMD=  0x7f971c00a740
Time slot   8
	CPU 2: Put process  1 to run queue
	CPU 2: Dispatched process  1
print_pgtbl:
 PDG=  0x7f971c007710 PDG=  0x7f971c007710 P4g=  0x7f971c008720 PUD=  0x7f971c009730 PMD=  0x7f971c00a740
Time slot   9
	Loaded a process at input/proc/s0, PID: 2 PRIO: 38
	CPU 3: Dispatched process  2
Time slot  10
	CPU 2: Put process  1 to run queue
	CPU 2: Dispatched process  1
Time slot  11
	Loaded a process at input/proc/s3, PID: 3 PRIO: 39
Time slot  12
	CPU 3: Put process  2 to run queue
	CPU 3: Dispatched process  2
	CPU 2: Put process  1 to run queue
	CPU 2: Dispatched process  3
	CPU 1: Dispatched process  1
Time slot  13
	CPU 2: Put process  3 to run queue
	CPU 2: Dispatched process  3
Time slot  14
	CPU 3: Put process  2 to run queue
	CPU 3: Dispatched process  2
	CPU 1: Put process  1 to run queue
	CPU 1: Dispatched process  1
	Loaded a process at input/proc/m2s, PID: 4 PRIO: 15
	CPU 0: Dispatched process  4
print_pgtbl:
 PDG=  0x7f971c01bb90 PDG=  0x7f971c01bb90 P4g=  0x7f971c01cba0 PUD=  0x7f971c01dbb0 PMD=  0x7f971c01ebc0
Time slot  15
print_pgtbl:
 PDG=  0x7f971c01bb90 PDG=  0x7f971c01bb90 P4g=  0x7f971c01cba0 PUD=  0x7f971c01dbb0 PMD=  0x7f971c01ebc0
print_pgtbl:
 PDG=  0x7f971c01bb90 PDG=  0x7f971c01bb90 P4g=  0x7f971c01cba0 PUD=  0x7f971c01dbb0 PMD=  0x7f971c01ebc0
	CPU 3: Put process  2 to run queue
	CPU 3: Dispatched process  2
Time slot  16
	CPU 2: Put process  3 to run queue
	CPU 2: Dispatched process  3
	CPU 1: Put process  1 to run queue
	CPU 1: Dispatched process  1
print_pgtbl:
 PDG=  0x7f971c01bb90 PDG=  0x7f971c01bb90 P4g=  0x7f971c01cba0 PUD=  0x7f971c01dbb0 PMD=  0x7f971c01ebc0
	Loaded a process at input/proc/s2, PID: 5 PRIO: 120
	CPU 0: Put process  4 to run queue
	CPU 0: Dispatched process  4
print_pgtbl:
 PDG=  0x7f971c022760 PDG=  0x7f971c022760 P4g=  0x7f971c023770 PUD=  0x7f971c024780 PMD=  0x7f971c025790
print_pgtbl:
 PDG=  0x7f971c022760 PDG=  0x7f971c022760 P4g=  0x7f971c023770 PUD=  0x7f971c024780 PMD=  0x7f971c025790
Time slot  17
	Loaded a process at input/proc/s1, PID: 6 PRIO: 0
	CPU 3: Put process  2 to run queue
	CPU 3: Dispatched process  6
	CPU 2: Put process  3 to run queue
	CPU 2: Dispatched process  2
	CPU 0: Put process  4 to run queue
	CPU 0: Dispatched process  4
	CPU 1: Processed  1 has finished
	CPU 1: Dispatched process  3
Time slot  18
Time slot  19
	CPU 3: Put process  6 to run queue
	CPU 3: Dispatched process  6
	CPU 2: Put process  2 to run queue
	CPU 2: Dispatched process  2
	CPU 1: Put process  3 to run queue
	CPU 1: Dispatched process  3
	CPU 0: Put process  4 to run queue
	CPU 0: Dispatched process  4
Time slot  20
Time slot  21
	CPU 3: Put process  6 to run queue
	CPU 3: Dispatched process  6
Time slot  22
	CPU 0: Put process  4 to run queue
	CPU 0: Dispatched process  4
	CPU 2: Put process  2 to run queue
	CPU 2: Dispatched process  2
	CPU 1: Put process  3 to run queue
	CPU 1: Dispatched process  3
Time slot  23
print_pgtbl:
 PDG=  0x7f971c0292b0 PDG=  0x7f971c0292b0 P4g=  0x7f971c02a2c0 PUD=  0x7f971c02b2d0 PMD=  0x7f971c02c2e0
	CPU 3: Put process  6 to run queue
	CPU 3: Dispatched process  6
	CPU 2: Put process  2 to run queue
	CPU 2: Dispatched process  2
	CPU 1: Put process  3 to run queue
	CPU 1: Dispatched process  3
Time slot  24
	CPU 0: Put process  4 to run queue
	CPU 0: Dispatched process  4
print_pgtbl:
 PDG=  0x7f971c0292b0 PDG=  0x7f971c0292b0 P4g=  0x7f971c02a2c0 PUD=  0x7f971c02b2d0 PMD=  0x7f971c02c2e0
Time slot  25
	CPU 2: Processed  2 has finished
	CPU 2: Dispatched process  5
print_pgtbl:
 PDG=  0x7f971c0292b0 PDG=  0x7f971c0292b0 P4g=  0x7f971c02a2c0 PUD=  0x7f971c02b2d0 PMD=  0x7f971c02c2e0
	CPU 1: Put process  3 to run queue
	CPU 1: Dispatched process  3
Time slot  26
	CPU 3: Put process  6 to run queue
	CPU 3: Dispatched process  6
	CPU 0: Processed  4 has finished
	CPU 0 stopped
Time slot  27
	CPU 2: Put process  5 to run queue
	CPU 2: Dispatched process  5
	CPU 3: Processed  6 has finished
	CPU 3 stopped
	CPU 1: Processed  3 has finished
	CPU 1 stopped
Time slot  28
Time slot  29
	CPU 2: Put process  5 to run queue
	CPU 2: Dispatched process  5
Time slot  30
Time slot  31
	CPU 2: Put process  5 to run queue
	CPU 2: Dispatched process  5
Time slot  32
	CPU 2: Put process  5 to run queue
	CPU 2: Dispatched process  5
Time slot  33
Time slot  34
Time slot  35
	CPU 2: Put process  5 to run queue
	CPU 2: Dispatched process  5
Time slot  36
Time slot  37
	CPU 2: Processed  5 has finished
	CPU 2 stopped
